[2025-04-06 17:51:16,228] {taskinstance.py:1032} INFO - Dependencies all met for <TaskInstance: data_ingestion_gcs_dag.download_dataset_task manual__2025-04-06T16:36:45.468529+00:00 [queued]>
[2025-04-06 17:51:16,236] {taskinstance.py:1032} INFO - Dependencies all met for <TaskInstance: data_ingestion_gcs_dag.download_dataset_task manual__2025-04-06T16:36:45.468529+00:00 [queued]>
[2025-04-06 17:51:16,236] {taskinstance.py:1238} INFO - 
--------------------------------------------------------------------------------
[2025-04-06 17:51:16,237] {taskinstance.py:1239} INFO - Starting attempt 1 of 2
[2025-04-06 17:51:16,237] {taskinstance.py:1240} INFO - 
--------------------------------------------------------------------------------
[2025-04-06 17:51:16,252] {taskinstance.py:1259} INFO - Executing <Task(BashOperator): download_dataset_task> on 2025-04-06 16:36:45.468529+00:00
[2025-04-06 17:51:16,259] {standard_task_runner.py:52} INFO - Started process 107 to run task
[2025-04-06 17:51:16,262] {standard_task_runner.py:76} INFO - Running: ['***', 'tasks', 'run', 'data_ingestion_gcs_dag', 'download_dataset_task', 'manual__2025-04-06T16:36:45.468529+00:00', '--job-id', '626', '--raw', '--subdir', 'DAGS_FOLDER/data_ingestion_gcs_dag.py', '--cfg-path', '/tmp/tmppnr_m2l5', '--error-file', '/tmp/tmpfekag_wz']
[2025-04-06 17:51:16,264] {standard_task_runner.py:77} INFO - Job 626: Subtask download_dataset_task
[2025-04-06 17:51:16,299] {logging_mixin.py:109} INFO - Running <TaskInstance: data_ingestion_gcs_dag.download_dataset_task manual__2025-04-06T16:36:45.468529+00:00 [running]> on host 2e34ec58e554
[2025-04-06 17:51:16,321] {taskinstance.py:1700} ERROR - Task failed with exception
Traceback (most recent call last):
  File "/home/airflow/.local/lib/python3.6/site-packages/sqlalchemy/engine/base.py", line 1277, in _execute_context
    cursor, statement, parameters, context
  File "/home/airflow/.local/lib/python3.6/site-packages/sqlalchemy/engine/default.py", line 608, in do_execute
    cursor.execute(statement, parameters)
psycopg2.errors.UndefinedColumn: column xcom.execution_date does not exist
LINE 1: ...g' AND xcom.task_id = 'download_dataset_task' AND xcom.execu...
                                                             ^


The above exception was the direct cause of the following exception:

Traceback (most recent call last):
  File "/home/airflow/.local/lib/python3.6/site-packages/airflow/models/taskinstance.py", line 1329, in _run_raw_task
    self._execute_task_with_callbacks(context)
  File "/home/airflow/.local/lib/python3.6/site-packages/airflow/models/taskinstance.py", line 1415, in _execute_task_with_callbacks
    self.clear_xcom_data()
  File "/home/airflow/.local/lib/python3.6/site-packages/airflow/utils/session.py", line 70, in wrapper
    return func(*args, session=session, **kwargs)
  File "/home/airflow/.local/lib/python3.6/site-packages/airflow/models/taskinstance.py", line 792, in clear_xcom_data
    session=session,
  File "/home/airflow/.local/lib/python3.6/site-packages/airflow/utils/session.py", line 67, in wrapper
    return func(*args, **kwargs)
  File "/home/airflow/.local/lib/python3.6/site-packages/airflow/models/xcom.py", line 323, in clear
    return query.delete()
  File "/home/airflow/.local/lib/python3.6/site-packages/sqlalchemy/orm/query.py", line 3926, in delete
    delete_op.exec_()
  File "/home/airflow/.local/lib/python3.6/site-packages/sqlalchemy/orm/persistence.py", line 1697, in exec_
    self._do_exec()
  File "/home/airflow/.local/lib/python3.6/site-packages/sqlalchemy/orm/persistence.py", line 1930, in _do_exec
    self._execute_stmt(delete_stmt)
  File "/home/airflow/.local/lib/python3.6/site-packages/sqlalchemy/orm/persistence.py", line 1702, in _execute_stmt
    self.result = self.query._execute_crud(stmt, self.mapper)
  File "/home/airflow/.local/lib/python3.6/site-packages/sqlalchemy/orm/query.py", line 3568, in _execute_crud
    return conn.execute(stmt, self._params)
  File "/home/airflow/.local/lib/python3.6/site-packages/sqlalchemy/engine/base.py", line 1011, in execute
    return meth(self, multiparams, params)
  File "/home/airflow/.local/lib/python3.6/site-packages/sqlalchemy/sql/elements.py", line 298, in _execute_on_connection
    return connection._execute_clauseelement(self, multiparams, params)
  File "/home/airflow/.local/lib/python3.6/site-packages/sqlalchemy/engine/base.py", line 1130, in _execute_clauseelement
    distilled_params,
  File "/home/airflow/.local/lib/python3.6/site-packages/sqlalchemy/engine/base.py", line 1317, in _execute_context
    e, statement, parameters, cursor, context
  File "/home/airflow/.local/lib/python3.6/site-packages/sqlalchemy/engine/base.py", line 1511, in _handle_dbapi_exception
    sqlalchemy_exception, with_traceback=exc_info[2], from_=e
  File "/home/airflow/.local/lib/python3.6/site-packages/sqlalchemy/util/compat.py", line 182, in raise_
    raise exception
  File "/home/airflow/.local/lib/python3.6/site-packages/sqlalchemy/engine/base.py", line 1277, in _execute_context
    cursor, statement, parameters, context
  File "/home/airflow/.local/lib/python3.6/site-packages/sqlalchemy/engine/default.py", line 608, in do_execute
    cursor.execute(statement, parameters)
sqlalchemy.exc.ProgrammingError: (psycopg2.errors.UndefinedColumn) column xcom.execution_date does not exist
LINE 1: ...g' AND xcom.task_id = 'download_dataset_task' AND xcom.execu...
                                                             ^

[SQL: DELETE FROM xcom WHERE xcom.dag_id = %(dag_id_1)s AND xcom.task_id = %(task_id_1)s AND xcom.execution_date = %(execution_date_1)s]
[parameters: {'dag_id_1': 'data_ingestion_gcs_dag', 'task_id_1': 'download_dataset_task', 'execution_date_1': datetime.datetime(2025, 4, 6, 16, 36, 45, 468529, tzinfo=Timezone('UTC'))}]
(Background on this error at: http://sqlalche.me/e/13/f405)
[2025-04-06 17:51:16,334] {taskinstance.py:1277} INFO - Marking task as UP_FOR_RETRY. dag_id=data_ingestion_gcs_dag, task_id=download_dataset_task, execution_date=20250406T163645, start_date=20250406T175116, end_date=20250406T175116
[2025-04-06 17:51:16,343] {standard_task_runner.py:92} ERROR - Failed to execute job 626 for task download_dataset_task
Traceback (most recent call last):
  File "/home/airflow/.local/lib/python3.6/site-packages/sqlalchemy/engine/base.py", line 1277, in _execute_context
    cursor, statement, parameters, context
  File "/home/airflow/.local/lib/python3.6/site-packages/sqlalchemy/engine/default.py", line 608, in do_execute
    cursor.execute(statement, parameters)
psycopg2.errors.UndefinedColumn: column xcom.execution_date does not exist
LINE 1: ...g' AND xcom.task_id = 'download_dataset_task' AND xcom.execu...
                                                             ^


The above exception was the direct cause of the following exception:

Traceback (most recent call last):
  File "/home/airflow/.local/lib/python3.6/site-packages/airflow/models/taskinstance.py", line 1329, in _run_raw_task
    self._execute_task_with_callbacks(context)
  File "/home/airflow/.local/lib/python3.6/site-packages/airflow/models/taskinstance.py", line 1415, in _execute_task_with_callbacks
    self.clear_xcom_data()
  File "/home/airflow/.local/lib/python3.6/site-packages/airflow/utils/session.py", line 70, in wrapper
    return func(*args, session=session, **kwargs)
  File "/home/airflow/.local/lib/python3.6/site-packages/airflow/models/taskinstance.py", line 792, in clear_xcom_data
    session=session,
  File "/home/airflow/.local/lib/python3.6/site-packages/airflow/utils/session.py", line 67, in wrapper
    return func(*args, **kwargs)
  File "/home/airflow/.local/lib/python3.6/site-packages/airflow/models/xcom.py", line 323, in clear
    return query.delete()
  File "/home/airflow/.local/lib/python3.6/site-packages/sqlalchemy/orm/query.py", line 3926, in delete
    delete_op.exec_()
  File "/home/airflow/.local/lib/python3.6/site-packages/sqlalchemy/orm/persistence.py", line 1697, in exec_
    self._do_exec()
  File "/home/airflow/.local/lib/python3.6/site-packages/sqlalchemy/orm/persistence.py", line 1930, in _do_exec
    self._execute_stmt(delete_stmt)
  File "/home/airflow/.local/lib/python3.6/site-packages/sqlalchemy/orm/persistence.py", line 1702, in _execute_stmt
    self.result = self.query._execute_crud(stmt, self.mapper)
  File "/home/airflow/.local/lib/python3.6/site-packages/sqlalchemy/orm/query.py", line 3568, in _execute_crud
    return conn.execute(stmt, self._params)
  File "/home/airflow/.local/lib/python3.6/site-packages/sqlalchemy/engine/base.py", line 1011, in execute
    return meth(self, multiparams, params)
  File "/home/airflow/.local/lib/python3.6/site-packages/sqlalchemy/sql/elements.py", line 298, in _execute_on_connection
    return connection._execute_clauseelement(self, multiparams, params)
  File "/home/airflow/.local/lib/python3.6/site-packages/sqlalchemy/engine/base.py", line 1130, in _execute_clauseelement
    distilled_params,
  File "/home/airflow/.local/lib/python3.6/site-packages/sqlalchemy/engine/base.py", line 1317, in _execute_context
    e, statement, parameters, cursor, context
  File "/home/airflow/.local/lib/python3.6/site-packages/sqlalchemy/engine/base.py", line 1511, in _handle_dbapi_exception
    sqlalchemy_exception, with_traceback=exc_info[2], from_=e
  File "/home/airflow/.local/lib/python3.6/site-packages/sqlalchemy/util/compat.py", line 182, in raise_
    raise exception
  File "/home/airflow/.local/lib/python3.6/site-packages/sqlalchemy/engine/base.py", line 1277, in _execute_context
    cursor, statement, parameters, context
  File "/home/airflow/.local/lib/python3.6/site-packages/sqlalchemy/engine/default.py", line 608, in do_execute
    cursor.execute(statement, parameters)
sqlalchemy.exc.ProgrammingError: (psycopg2.errors.UndefinedColumn) column xcom.execution_date does not exist
LINE 1: ...g' AND xcom.task_id = 'download_dataset_task' AND xcom.execu...
                                                             ^

[SQL: DELETE FROM xcom WHERE xcom.dag_id = %(dag_id_1)s AND xcom.task_id = %(task_id_1)s AND xcom.execution_date = %(execution_date_1)s]
[parameters: {'dag_id_1': 'data_ingestion_gcs_dag', 'task_id_1': 'download_dataset_task', 'execution_date_1': datetime.datetime(2025, 4, 6, 16, 36, 45, 468529, tzinfo=Timezone('UTC'))}]
(Background on this error at: http://sqlalche.me/e/13/f405)

During handling of the above exception, another exception occurred:

Traceback (most recent call last):
  File "/home/airflow/.local/lib/python3.6/site-packages/sqlalchemy/engine/base.py", line 1277, in _execute_context
    cursor, statement, parameters, context
  File "/home/airflow/.local/lib/python3.6/site-packages/sqlalchemy/engine/default.py", line 608, in do_execute
    cursor.execute(statement, parameters)
psycopg2.errors.UndefinedColumn: column "execution_date" of relation "task_fail" does not exist
LINE 1: INSERT INTO task_fail (task_id, dag_id, execution_date, star...
                                                ^


The above exception was the direct cause of the following exception:

Traceback (most recent call last):
  File "/home/airflow/.local/lib/python3.6/site-packages/airflow/task/task_runner/standard_task_runner.py", line 85, in _start_by_fork
    args.func(args, dag=self.dag)
  File "/home/airflow/.local/lib/python3.6/site-packages/airflow/cli/cli_parser.py", line 48, in command
    return func(*args, **kwargs)
  File "/home/airflow/.local/lib/python3.6/site-packages/airflow/utils/cli.py", line 92, in wrapper
    return f(*args, **kwargs)
  File "/home/airflow/.local/lib/python3.6/site-packages/airflow/cli/commands/task_command.py", line 298, in task_run
    _run_task_by_selected_method(args, dag, ti)
  File "/home/airflow/.local/lib/python3.6/site-packages/airflow/cli/commands/task_command.py", line 107, in _run_task_by_selected_method
    _run_raw_task(args, ti)
  File "/home/airflow/.local/lib/python3.6/site-packages/airflow/cli/commands/task_command.py", line 184, in _run_raw_task
    error_file=args.error_file,
  File "/home/airflow/.local/lib/python3.6/site-packages/airflow/utils/session.py", line 70, in wrapper
    return func(*args, session=session, **kwargs)
  File "/home/airflow/.local/lib/python3.6/site-packages/airflow/models/taskinstance.py", line 1386, in _run_raw_task
    self.handle_failure(e, test_mode, error_file=error_file, session=session)
  File "/home/airflow/.local/lib/python3.6/site-packages/airflow/utils/session.py", line 67, in wrapper
    return func(*args, **kwargs)
  File "/home/airflow/.local/lib/python3.6/site-packages/airflow/models/taskinstance.py", line 1755, in handle_failure
    session.flush()
  File "/home/airflow/.local/lib/python3.6/site-packages/sqlalchemy/orm/session.py", line 2540, in flush
    self._flush(objects)
  File "/home/airflow/.local/lib/python3.6/site-packages/sqlalchemy/orm/session.py", line 2682, in _flush
    transaction.rollback(_capture_exception=True)
  File "/home/airflow/.local/lib/python3.6/site-packages/sqlalchemy/util/langhelpers.py", line 70, in __exit__
    with_traceback=exc_tb,
  File "/home/airflow/.local/lib/python3.6/site-packages/sqlalchemy/util/compat.py", line 182, in raise_
    raise exception
  File "/home/airflow/.local/lib/python3.6/site-packages/sqlalchemy/orm/session.py", line 2642, in _flush
    flush_context.execute()
  File "/home/airflow/.local/lib/python3.6/site-packages/sqlalchemy/orm/unitofwork.py", line 422, in execute
    rec.execute(self)
  File "/home/airflow/.local/lib/python3.6/site-packages/sqlalchemy/orm/unitofwork.py", line 589, in execute
    uow,
  File "/home/airflow/.local/lib/python3.6/site-packages/sqlalchemy/orm/persistence.py", line 245, in save_obj
    insert,
  File "/home/airflow/.local/lib/python3.6/site-packages/sqlalchemy/orm/persistence.py", line 1136, in _emit_insert_statements
    statement, params
  File "/home/airflow/.local/lib/python3.6/site-packages/sqlalchemy/engine/base.py", line 1011, in execute
    return meth(self, multiparams, params)
  File "/home/airflow/.local/lib/python3.6/site-packages/sqlalchemy/sql/elements.py", line 298, in _execute_on_connection
    return connection._execute_clauseelement(self, multiparams, params)
  File "/home/airflow/.local/lib/python3.6/site-packages/sqlalchemy/engine/base.py", line 1130, in _execute_clauseelement
    distilled_params,
  File "/home/airflow/.local/lib/python3.6/site-packages/sqlalchemy/engine/base.py", line 1317, in _execute_context
    e, statement, parameters, cursor, context
  File "/home/airflow/.local/lib/python3.6/site-packages/sqlalchemy/engine/base.py", line 1511, in _handle_dbapi_exception
    sqlalchemy_exception, with_traceback=exc_info[2], from_=e
  File "/home/airflow/.local/lib/python3.6/site-packages/sqlalchemy/util/compat.py", line 182, in raise_
    raise exception
  File "/home/airflow/.local/lib/python3.6/site-packages/sqlalchemy/engine/base.py", line 1277, in _execute_context
    cursor, statement, parameters, context
  File "/home/airflow/.local/lib/python3.6/site-packages/sqlalchemy/engine/default.py", line 608, in do_execute
    cursor.execute(statement, parameters)
sqlalchemy.exc.ProgrammingError: (psycopg2.errors.UndefinedColumn) column "execution_date" of relation "task_fail" does not exist
LINE 1: INSERT INTO task_fail (task_id, dag_id, execution_date, star...
                                                ^

[SQL: INSERT INTO task_fail (task_id, dag_id, execution_date, start_date, end_date, duration) VALUES (%(task_id)s, %(dag_id)s, %(execution_date)s, %(start_date)s, %(end_date)s, %(duration)s) RETURNING task_fail.id]
[parameters: {'task_id': 'download_dataset_task', 'dag_id': 'data_ingestion_gcs_dag', 'execution_date': datetime.datetime(2025, 4, 6, 16, 36, 45, 468529, tzinfo=Timezone('UTC')), 'start_date': datetime.datetime(2025, 4, 6, 17, 51, 16, 229621, tzinfo=Timezone('UTC')), 'end_date': datetime.datetime(2025, 4, 6, 17, 51, 16, 333967, tzinfo=Timezone('UTC')), 'duration': 0}]
(Background on this error at: http://sqlalche.me/e/13/f405)
[2025-04-06 17:51:16,355] {local_task_job.py:154} INFO - Task exited with return code 1
[2025-04-06 17:51:16,386] {taskinstance.py:1277} INFO - Marking task as UP_FOR_RETRY. dag_id=data_ingestion_gcs_dag, task_id=download_dataset_task, execution_date=20250406T163645, start_date=20250406T175116, end_date=20250406T175116
